Workbook

Sheet Problem Statement
A1: Problem statement
A2: This study looks at 55 people in the U.S. to understand why health insurance costs vary. We want to see if a person’s gender or where they live (Southwest, Southeast, Northwest, or Northeast) changes how much they pay. We are also checking if there are more smokers in one gender than the other. The results will help insurance companies set fairer prices and create better plans for different regions.
A9: Q1 (Part a — Descriptive Statistics): What is the overall distribution of insurance charges (USD) among the sampled policyholders, and what are the key descriptive measures such as mean, median, standard deviation, and skewness?
A12: Q2 (Part b — Confidence Interval): What is the 95% confidence interval for the true population mean of insurance charges (USD) based on the given sample?
A14: Q3 (Part c — F-test and t-test): Is there a significant difference in the variance of insurance charges between male and female policyholders at 5% level of significance? And Is there a significant difference in the mean insurance charges between male and female policyholders at 5% level of significance?
A18: Q4 (Part d — Z-test): Is there a significant difference in the proportion of smokers between male and female policyholders at 5% level of significance?
A20: Q5 (Part e — ANOVA): Is there a significant difference in the mean insurance charges across the four geographic regions (Southwest, Southeast, Northwest, Northeast) at 5% level of significance?
A22: Q6 (Part f — Tukey-Kramer): If regional differences exist, which specific pairs of regions differ significantly in their mean insurance charges?

Sheet Task 01 Data
A1: Age | B1: Sex | C1: BMI | D1: Children | E1: Smoker | F1: Region | G1: Charges ($) | I1: Male | J1: Female | L1: Male | M1: Female | O1: SW | P1: SE | Q1: NW | R1: NE
A2: 19 | B2: female | C2: 27.9 | D2: 0 | E2: yes | F2: southwest | G2: 16884.92 | I2: 1725.5523 | J2: 16884.92 | K2: Sample Mean | L2: =AVERAGE(I2:I30) -> 17189.36 | M2: =AVERAGE(J2:J27) -> 10800.93 | O2: 16884.92 | P2: 1725.5523 | Q2: 21984.471 | R2: 6406.4107
A3: 18 | B3: male | C3: 33.77 | D3: 1 | E3: no | F3: southeast | G3: 1725.5523 | I3: 4449.462 | J3: 3756.6216 | K3: Standard Deviation | L3: =_xlfn.STDEV.S(I2:I30) -> 17167.479 | M3: =_xlfn.STDEV.S(J2:J27) -> 8980.0491 | O3: 1826.843 | P3: 4449.462 | Q3: 3866.8552 | R3: 2721.3208
A4: 28 | B4: male | C4: 33 | D4: 3 | E4: no | F4: southeast | G4: 4449.462 | I4: 21984.471 | J4: 8240.5896 | K4: Var Male | L4: =_xlfn.VAR.S(I2:I30) -> 2.9472233e+08 | O4: 1837.237 | P4: 3756.6216 | Q4: 7281.5056 | R4: 10797.336
A5: 33 | B5: male | C5: 22.705 | D5: 0 | E5: no | F5: northwest | G5: 21984.471 | I5: 3866.8552 | J5: 7281.5056 | K5: Var Female | L5: =_xlfn.VAR.S(J2:J27) -> 80641282 | O5: 10602.385 | P5: 8240.5896 | Q5: 28923.137 | R5: 2395.1716
A6: 32 | B6: male | C6: 28.88 | D6: 0 | E6: no | F6: northwest | G6: 3866.8552 | I6: 6406.4107 | J6: 28923.137 | O6: 36837.467 | P6: 27808.725 | Q6: 6203.9017 | R6: 13228.847
A7: 31 | B7: female | C7: 25.74 | D7: 0 | E7: no | F7: southeast | G7: 3756.6216 | I7: 2721.3208 | J7: 27808.725 | O7: 4149.736 | P7: 11090.718 | Q7: 12268.632 | R7: 37701.877
A8: 46 | B8: female | C8: 33.44 | D8: 1 | E8: no | F8: southeast | G8: 8240.5896 | I8: 1826.843 | J8: 11090.718 | O8: 38711 | P8: 39611.758 | Q8: 2775.1921 | R8: 14451.835
A9: 37 | B9: female | C9: 27.74 | D9: 3 | E9: no | F9: northwest | G9: 7281.5056 | I9: 39611.758 | J9: 10797.336 | O9: 35585.576 | P9: 1137.011 | Q9: 13770.098 | R9: 2198.1899
A10: 37 | B10: male | C10: 29.83 | D10: 2 | E10: no | F10: northeast | G10: 6406.4107 | I10: 1837.237 | J10: 13228.847 | O10: 4687.797 | P10: 14001.134 | Q10: 1625.4337 | R10: 39774.276
A11: 60 | B11: female | C11: 25.84 | D11: 0 | E11: no | F11: northwest | G11: 28923.137 | I11: 2395.1716 | J11: 4149.736 | O11: 51194.559 | P11: 4949.7587 | Q11: 15612.193 | R11: 3046.062
A12: 25 | B12: male | C12: 26.22 | D12: 0 | E12: no | F12: northeast | G12: 2721.3208 | I12: 10602.385 | J12: 37701.877 | O12: 2302.3 | P12: 6272.4772 | Q12: 3556.9223 | R12: 6079.6715
A13: 62 | B13: female | C13: 26.29 | D13: 0 | E13: yes | F13: southeast | G13: 27808.725 | I13: 36837.467 | J13: 14001.134 | O13: 48173.361 | P13: 6313.759 | Q13: 3579.8287 | R13: 3393.3564
A14: 23 | B14: male | C14: 34.4 | D14: 0 | E14: no | F14: southwest | G14: 1826.843 | I14: 1137.011 | J14: 14451.835 | O14: 10601.632 | P14: 12629.897 | Q14: 8059.6791 | R14: 2211.1307
A15: 56 | B15: female | C15: 39.82 | D15: 0 | E15: no | F15: southeast | G15: 11090.718 | I15: 6203.9017 | J15: 12268.632 | O15: 23568.272 | P15: 38709.176
A16: 27 | B16: male | C16: 42.13 | D16: 0 | E16: yes | F16: southeast | G16: 39611.758 | I16: 2775.1921 | J16: 2198.1899 | P16: 37742.576
A17: 19 | B17: male | C17: 24.6 | D17: 1 | E17: no | F17: southwest | G17: 1837.237 | I17: 38711 | J17: 4687.797
A18: 52 | B18: female | C18: 30.78 | D18: 1 | E18: no | F18: northeast | G18: 10797.336 | I18: 35585.576 | J18: 15612.193
A19: 23 | B19: male | C19: 23.845 | D19: 0 | E19: no | F19: northeast | G19: 2395.1716 | I19: 13770.098 | J19: 3046.062
A20: 56 | B20: male | C20: 40.3 | D20: 0 | E20: no | F20: southwest | G20: 10602.385 | I20: 51194.559 | J20: 4949.7587
A21: 30 | B21: male | C21: 35.3 | D21: 0 | E21: yes | F21: southwest | G21: 36837.467 | I21: 1625.4337 | J21: 6313.759
A22: 60 | B22: female | C22: 36.005 | D22: 0 | E22: no | F22: northeast | G22: 13228.847 | I22: 2302.3 | J22: 3393.3564
A23: 30 | B23: female | C23: 32.4 | D23: 1 | E23: no | F23: southwest | G23: 4149.736 | I23: 39774.276 | J23: 3556.9223
A24: 18 | B24: male | C24: 34.1 | D24: 0 | E24: no | F24: southeast | G24: 1137.011 | I24: 48173.361 | J24: 12629.897
A25: 34 | B25: female | C25: 31.92 | D25: 1 | E25: yes | F25: northeast | G25: 37701.877 | I25: 6272.4772 | J25: 2211.1307
A26: 37 | B26: male | C26: 28.025 | D26: 2 | E26: no | F26: northwest | G26: 6203.9017 | I26: 6079.6715 | J26: 3579.8287
A27: 59 | B27: female | C27: 27.72 | D27: 3 | E27: no | F27: southeast | G27: 14001.134 | I27: 10601.632 | J27: 8059.6791
A28: 63 | B28: female | C28: 23.085 | D28: 0 | E28: no | F28: northeast | G28: 14451.835 | I28: 38709.176
A29: 55 | B29: female | C29: 32.775 | D29: 2 | E29: no | F29: northwest | G29: 12268.632 | I29: 23568.272
A30: 23 | B30: male | C30: 17.385 | D30: 1 | E30: no | F30: northwest | G30: 2775.1921 | I30: 37742.576
A31: 31 | B31: male | C31: 36.3 | D31: 2 | E31: yes | F31: southwest | G31: 38711
A32: 22 | B32: male | C32: 35.6 | D32: 0 | E32: yes | F32: southwest | G32: 35585.576
A33: 18 | B33: female | C33: 26.315 | D33: 0 | E33: no | F33: northeast | G33: 2198.1899
A34: 19 | B34: female | C34: 28.6 | D34: 5 | E34: no | F34: southwest | G34: 4687.797
A35: 63 | B35: male | C35: 28.31 | D35: 0 | E35: no | F35: northwest | G35: 13770.098
A36: 28 | B36: male | C36: 36.4 | D36: 1 | E36: yes | F36: southwest | G36: 51194.559
A37: 19 | B37: male | C37: 20.425 | D37: 0 | E37: no | F37: northwest | G37: 1625.4337
A38: 62 | B38: female | C38: 32.965 | D38: 3 | E38: no | F38: northwest | G38: 15612.193
A39: 26 | B39: male | C39: 20.8 | D39: 0 | E39: no | F39: southwest | G39: 2302.3
A40: 35 | B40: male | C40: 36.67 | D40: 1 | E40: yes | F40: northeast | G40: 39774.276
...

Sheet T01. Part a. DS
A2: Descriptive Statistics
A3: Charges ($)
A5: Mean | B5: 14169.375
A6: Standard Error | B6: 1909.3738
A7: Median | B7: 8059.6791
A8: Mode | B8: #N/A
A9: Standard Deviation | B9: 14160.295
A10: Sample Variance | B10: 2.0051395e+08
A11: Kurtosis | B11: 0.093603745
A12: Skewness | B12: 1.1762279
A13: Range | B13: 50057.548
A14: Minimum | B14: 1137.011
A15: Maximum | B15: 51194.559
A16: Sum | B16: 779315.63
A17: Count | B17: 55
A18: Confidence Level(95.0%) | B18: 3828.0639

Sheet T01. Part b. CI
A1: Confidence Interval
A3: Data
A4: Sample Standard Deviation | B4: 14160.29
A5: Sample Mean | B5: 14169.38
A6: Sample Size | B6: 55
A7: Confidence Level | B7: 0.95
A9: Intermediate Calculations
A10: Standard Error of the Mean | B10: =B4/SQRT(B6) -> 1909.3731
A11: Degrees of Freedom | B11: =B6-1 -> 54
A12: t Value | B12: =_xlfn.T.INV.2T(1-B7, B11) -> 2.0048793
A13: Interval Half Width | B13: =B12*B10 -> 3828.0626
A15: Confidence Interval
A16: Interval Lower Limit | B16: =B5-B13 -> 10341.317
A17: Interval Upper Limit | B17: =B5+B13 -> 17997.443
A19: Interpretation
A20: We are 95% confident that the true population mean of insurance charges lies between $10,341.32 and $17,997.44.

Sheet T01. Part c. t-test
A1: t-Test: Two-Sample Assuming Unequal Variances
B3: Male | C3: Female
A4: Mean | B4: 17189.36 | C4: 10800.93
A5: Variance | B5: 2.9472233e+08 | C5: 80641282
A6: Observations | B6: 29 | C6: 26
A7: Hypothesized Mean Difference | B7: 0
A8: df | B8: 43
A9: t Stat | B9: 1.754082
A10: P(T<=t) one-tail | B10: 0.043270757
A11: t Critical one-tail | B11: 1.6810707
A12: P(T<=t) two-tail | B12: 0.086541514
A13: t Critical two-tail | B13: 2.0166922
A15: Hypothesis
A16: H₀: Mean insurance charges of Males = Mean insurance charges of Females
A17: H₁: Mean insurance charges of Males ≠ Mean insurance charges of Females
A19: Decision;
A20: We fail to reject the null hypothesis because p-value (0.0865) is greater than the significance level (0.05) and there is no statistically significant difference in mean insurance charges between male and female policyholders at 5% significance level.

Sheet T01. Part c. F-test
A1: F Test for Differences in Two Variances
A3: Data
A4: Level of Significance | B4: 0.05
A5: Larger-Variance Sample
A6: Sample Size | B6: 29
A7: Sample Variance | B7: 2.9472233e+08
A8: Smaller-Variance Sample
A9: Sample Size | B9: 26
A10: Sample Variance | B10: 80641282
A12: Intermediate Calculations
A13: F Test Statistic | B13: =B7/B10 -> 3.6547327
A14: Population 1 Sample Degrees of Freedom | B14: =B6-1 -> 28
A15: Population 2 Sample Degrees of Freedom | B15: =B9-1 -> 25
D16: Calculations Area
A17: Two-Tail Test | D17: F.DIST.RT value | E17: =_xlfn.F.DIST.RT(B13, B14, B15) -> 0.00081006714
A18: Upper Critical Value | B18: =_xlfn.F.INV.RT(B4/2, B14, B15) -> 2.1991969
A19: p-Value | B19: =2*E17 -> 0.0016201343
A20: =IF(B19<B4, "Reject the null hypothesis", "Do not reject the null hypothesis") -> Reject the null hypothesis
A22: Hypothesis
A23: H₀: Variance of Male charges = Variance of Female charges
A24: H₁: Variance of Male charges ≠ Variance of Female charges
A26: Decision
A27: We reject the null hypothesis because p-value (0.00162) is less than the significance level (0.05) and there is a statistically significant difference in the variance of insurance charges between male and female policyholders at 5% significance level. F-stat (3.6547) > F-crit (2.1992) So rejct

Sheet T01. Part d Z-test
A1: Two-Sample Test for Equality of Proportions
A2: Z-test
A3: Data | D3: Confidence Interval Estimate
A4: Hypothesized Difference | B4: 0 | D4: of the Difference Between Two Proportions
A5: Level of Significance | B5: 0.05
A6: Group 1 | D6: Data
A7: Number of Items of Interest | B7: 10 | D7: Confidence Level | E7: 0.95
A8: Sample Size | B8: 29
A9: Group 2 | D9: Intermediate Calculations
A10: Number of Items of Interest | B10: 3 | D10: Z Value | E10: =_xlfn.NORM.S.INV((1-E7)/2) -> -1.959964
A11: Sample Size | B11: 26 | D11: Std. Error of the Diff. between two Proportions | E11: =SQRT((B14*(1-B14)/B8)+(B15*(1-B15)/B11)) -> 0.10824142
D12: Interval Half Width | E12: =ABS(E10*E11) -> 0.21214929
A13: Intermediate Calculations
A14: Group 1 Proportion | B14: =B7/B8 -> 0.34482759 | D14: Confidence Interval
A15: Group 2 Proportion | B15: =B10/B11 -> 0.11538462 | D15: Interval Lower Limit | E15: =B16-E12 -> 0.017293684
A16: Difference in Two Proportions | B16: =B14-B15 -> 0.22944297 | D16: Interval Upper Limit | E16: =B16+E12 -> 0.44159226
A17: Average Proportion | B17: =(B7+B10)/(B8+B11) -> 0.23636364
A18: Z Test Statistic | B18: =(B16-B4)/SQRT(B17*(1-B17)*(1/B8+1/B11)) -> 1.9996107
A20: Two-Tail Test
A21: Lower Critical Value | B21: =_xlfn.NORM.S.INV(B5/2) -> -1.959964
A22: Upper Critical Value | B22: =_xlfn.NORM.S.INV(1-B5/2) -> 1.959964
A23: p-Value | B23: =2*(1-_xlfn.NORM.S.DIST(ABS(B18),TRUE)) -> 0.045542317
A24: =IF(B23<$B$5, "Reject the null hypothesis", "Do not reject the null hypothesis") -> Reject the null hypothesis
A26: Hypothesis
A27: H₀: Proportion of Male smokers = Proportion of Female smokers
A28: H₁: Proportion of Male smokers ≠ Proportion of Female smokers
A30: Ddecision
A31: We reject the null hypothesis because p-value (0.0455) is less than the significance level (0.05) and there is a statistically significant difference in the proportion of smokers between male and female policyholders at 5% significance level.

Sheet T01. Part e. ANOVA
A1: ANOVA: Single Factor | I1: Calculations
I2: c | J2: =COUNTA(ASFData!$1:$1) -> 4
A3: SUMMARY | I3: n | J3: =SUM(B5:B8) -> 55
A4: Groups | B4: Count | C4: Sum | D4: Average | E4: Variance
A5: SW | B5: =COUNT(ASFData!$A:$A) -> 14 | C5: =SUM(ASFData!$A:$A) -> 286963.09 | D5: =AVERAGE(ASFData!$A:$A) -> 20497.363 | E5: =_xlfn.VAR.S(ASFData!$A:$A) -> 3.30617e+08
A6: SE | B6: =COUNT(ASFData!$B:$B) -> 15 | C6: =SUM(ASFData!$B:$B) -> 218439.21 | D6: =AVERAGE(ASFData!$B:$B) -> 14562.614 | E6: =_xlfn.VAR.S(ASFData!$B:$B) -> 1.9804415e+08
A7: NW | B7: =COUNT(ASFData!$C:$C) -> 13 | C7: =SUM(ASFData!$C:$C) -> 129507.85 | D7: =AVERAGE(ASFData!$C:$C) -> 9962.1423 | E7: =_xlfn.VAR.S(ASFData!$C:$C) -> 68399583
A8: NE | B8: =COUNT(ASFData!$D:$D) -> 13 | C8: =SUM(ASFData!$D:$D) -> 144405.48 | D8: =AVERAGE(ASFData!$D:$D) -> 11108.114 | E8: =_xlfn.VAR.S(ASFData!$D:$D) -> 1.6845448e+08
A11: ANOVA
A12: Source of Variation | B12: SS | C12: df | D12: MS | E12: F | F12: P-value | G12: F crit
A13: Between Groups | B13: =B16-DEVSQ(ASFData!$A:$A)-DEVSQ(ASFData!$B:$B)-DEVSQ(ASFData!$C:$C)-DEVSQ(ASFData!$D:$D) -> 9.1486527e+08 | C13: =J2-1 -> 3 | D13: =B13/C13 -> 3.0495509e+08 | E13: =D13/D14 -> 1.5689383 | F13: =_xlfn.F.DIST.RT(E13,C13,C14) -> 0.20826082 | G13: =_xlfn.F.INV.RT(G17,C13,C14) -> 2.7862288
A14: Within Groups | B14: =B16-B13 -> 9.9128879e+09 | C14: =J3-COUNTA(ASFData!$1:$1) -> 51 | D14: =B14/C14 -> 1.9437035e+08
A16: Total | B16: =DEVSQ(ASFData!$A$1:$D$16) -> 1.0827753e+10 | C16: =C13+C14 -> 54
D17: Level of significance | G17: 0.05
A20: Hypothesis
A21: H₀:
A22: H₁: At least one region's mean insurance charges is different
A24: Decision
A25: We fail to reject the null hypothesis because F-stats (1.5689) is less than the critical value (2.7862). There is no statistically significant difference in mean insurance charges across the four US regions at 5% significance level.

Sheet T01. Part f. TukeyKramer
A1: Tukey-Kramer Multiple Comparisons
B3: Sample | C3: Sample | F3: Absolute | G3: Std. Error | H3: Critical
A4: Group | B4: Mean | C4: Size | E4: Comparison | F4: Difference | G4: of Difference | H4: Range | I4: =IF(B15="","Results are NOT valid until Q Statistic is entered into B15","Results") -> Results
A5: 1: SW | B5: ='T01. Part e. ANOVA'!D5 -> 20497.363 | C5: ='T01. Part e. ANOVA'!B5 -> 14 | E5: Group 1 to Group 2 | F5: =ABS($B$5-$B$6) -> 5934.7489 | G5: =SQRT(($B$14/2)*((1/$C$5)+(1/$C$6))) -> 3663.4424 | H5: =$B$15*$G$5 -> 13774.543 | I5: =IF($F$5>$H$5,"Means are different","Means are not different") -> Means are not different
A6: 2: SE | B6: ='T01. Part e. ANOVA'!D6 -> 14562.614 | C6: ='T01. Part e. ANOVA'!B6 -> 15 | E6: Group 1 to Group 3 | F6: =ABS($B$5-$B$7) -> 10535.221 | G6: =SQRT(($B$14/2)*((1/$C$5)+(1/$C$7))) -> 3797.049 | H6: =$B$15*$G$6 -> 14276.904 | I6: =IF($F$6>$H$6,"Means are different","Means are not different") -> Means are not different
A7: 3: NW | B7: ='T01. Part e. ANOVA'!D7 -> 9962.1423 | C7: ='T01. Part e. ANOVA'!B7 -> 13 | E7: Group 1 to Group 4 | F7: =ABS($B$5-$B$8) -> 9389.249 | G7: =SQRT(($B$14/2)*((1/$C$5)+(1/$C$8))) -> 3797.049 | H7: =$B$15*$G$7 -> 14276.904 | I7: =IF($F$7>$H$7,"Means are different","Means are not different") -> Means are not different
A8: 4: NE | B8: ='T01. Part e. ANOVA'!D8 -> 11108.114 | C8: ='T01. Part e. ANOVA'!B8 -> 13 | E8: Group 2 to Group 3 | F8: =ABS($B$6-$B$7) -> 4600.472 | G8: =SQRT(($B$14/2)*((1/$C$6)+(1/$C$7))) -> 3735.6116 | H8: =$B$15*$G$8 -> 14045.9 | I8: =IF($F$8>$H$8,"Means are different","Means are not different") -> Means are not different
E9: Group 2 to Group 4 | F9: =ABS($B$6-$B$8) -> 3454.5001 | G9: =SQRT(($B$14/2)*((1/$C$6)+(1/$C$8))) -> 3735.6116 | H9: =$B$15*$G$9 -> 14045.9 | I9: =IF($F$9>$H$9,"Means are different","Means are not different") -> Means are not different
A10: Other Data | E10: Group 3 to Group 4 | F10: =ABS($B$7-$B$8) -> 1145.9719 | G10: =SQRT(($B$14/2)*((1/$C$7)+(1/$C$8))) -> 3866.7254 | H10: =$B$15*$G$10 -> 14538.888 | I10: =IF($F$10>$H$10,"Means are different","Means are not different") -> Means are not different
A11: Level of significance | B11: ='T01. Part e. ANOVA'!G17 -> 0.05
A12: Numerator d.f. | B12: 4
A13: Denominator d.f. | B13: ='T01. Part e. ANOVA'!C14 -> 51
A14: MSW | B14: ='T01. Part e. ANOVA'!D14 -> 1.9437035e+08
A15: Q Statistic | B15: 3.76
A18: Hypothesis
A19: H₀:
A20: H₁: At least one region's mean insurance charges is different
A22: Decision
A23: We fail to reject the null hypothesis for all six pairwise comparisons. No pair of regions shows a statistically significant difference in mean insurance charges at 5% significance level.

Sheet ASFData
A1: SW | B1: SE | C1: NW | D1: NE
A2: 16884.92 | B2: 1725.5523 | C2: 21984.471 | D2: 6406.4107
A3: 1826.843 | B3: 4449.462 | C3: 3866.8552 | D3: 2721.3208
A4: 1837.237 | B4: 3756.6216 | C4: 7281.5056 | D4: 10797.336
A5: 10602.385 | B5: 8240.5896 | C5: 28923.137 | D5: 2395.1716
A6: 36837.467 | B6: 27808.725 | C6: 6203.9017 | D6: 13228.847
A7: 4149.736 | B7: 11090.718 | C7: 12268.632 | D7: 37701.877
A8: 38711 | B8: 39611.758 | C8: 2775.1921 | D8: 14451.835
A9: 35585.576 | B9: 1137.011 | C9: 13770.098 | D9: 2198.1899
A10: 4687.797 | B10: 14001.134 | C10: 1625.4337 | D10: 39774.276
A11: 51194.559 | B11: 4949.7587 | C11: 15612.193 | D11: 3046.062
A12: 2302.3 | B12: 6272.4772 | C12: 3556.9223 | D12: 6079.6715
A13: 48173.361 | B13: 6313.759 | C13: 3579.8287 | D13: 3393.3564
A14: 10601.632 | B14: 12629.897 | C14: 8059.6791 | D14: 2211.1307
A15: 23568.272 | B15: 38709.176
B16: 37742.576
